<mujoco>
	<option gravity="0 0 0"/>

	<!-- <contact>
        <pair geom1="wall" geom2="link1"/>
		<pair geom1="wall" geom2="link2"/>
    </contact> -->

	<worldbody>
        <light diffuse=".5 .5 .5" pos="0 0 10" dir="0 0 -1"/>

		<!-- ground -->
		<geom type="plane" pos="0 0 0" size="0 0 0.1" rgba="1 1 1 1"/>

		<!-- wall -->
		<geom name="wall" type="box" pos="1.8 0.0 2.0" euler="0 90 0" size="2 2 0.3" rgba="1 1 1 1" mass="1" condim="1" priority="2"/>

		<!-- link 1 -->
		<body pos="0.5 0 0.1" euler="0 90 0">
			<joint name="pin1" type="hinge" axis="-1 0 0"  pos="0 0 -0.5"  />
			<geom name="link1" type="cylinder" size=".05 0.5" rgba="1 0 0 1" mass="1"  condim="1"/>

			<!-- link 2 -->
			<body pos="0.0 0 1.0" euler="0 0 0">
				<joint name="pin2" type="hinge" axis="-1 0 0" pos="0 0 -0.5"/>
				<geom name="link2" type="cylinder" size=".05 0.5" rgba="0 1 0 1" mass="1" condim="1"/>
				<!-- <site name="tip" size="0.1" pos="0 0 0.5"/> -->
				<!-- gripper -->
				<body name="dummy body" pos="0 0 0.5">
					 <inertial pos="0 0 0" mass="0.0001" diaginertia="0 0 0" />
					 <geom type="sphere" pos="0 0 0" size="0.05" rgba="0 0 1 1"/>
					 <site name="tip" pos="0 0 0" rgba="1 0 0 0" size="0.01"/>
				</body>
			</body>
		</body>
	</worldbody>
	<sensor>
		<framepos objtype="site" objname="tip"/>
		<framelinvel objtype="site" objname="tip"/>
		<force site="tip"/> 
	</sensor>
	<actuator>
		<motor joint="pin1" name= "torque1" gear="1" ctrllimited="true" ctrlrange="-100 100"/>
		<motor joint="pin2" name= "torque2" gear="1" ctrllimited="true" ctrlrange="-100 100"/>
	</actuator>
</mujoco>
